<?xml version="1.0"?>
<robot name="my_robot">
  <link name="base_link"/>
  
  <joint name="laser_joint" type="fixed">
    <parent link="base_link"/>
    <child link="laser_link"/>
    <origin xyz="0.1 0 0.2" rpy="0 0 0"/>
  </joint>
  
  <link name="laser_link"/>
  
  <!-- 差速驱动配置 -->
  <joint name="wheel_left_joint" type="continuous">
    <parent link="base_link"/>
    <child link="wheel_left"/>
    <origin xyz="-0.1 0.15 0" rpy="0 0 0"/>
    <axis xyz="0 1 0"/>
  </joint>
  
  <link name="wheel_left"/>
  
  <joint name="wheel_right_joint" type="continuous">
    <parent link="base_link"/>
    <child link="wheel_right"/>
    <origin xyz="-0.1 -0.15 0" rpy="0 0 0"/>
    <axis xyz="0 1 0"/>
  </joint>
  
  <link name="wheel_right"/>
</robot>